Workbook

Sheet Top Redes
B1: TOP REDES | D1: META REDES | E1: META TOPS | F1: Realizado R$ | G1: % REDES | H1: % TOPS | I1: A Faturar R$ | J1: Faltando R$ | K1: %Fat + a Faturar REDES | L1: %Fat + a Fat TOPS | M1: Última atualização
B2: JULHO | D2: =SUBTOTAL(9,D4:D29) -> 3500696.6 | E2: =SUBTOTAL(9,E4:E29) -> 2569994.7 | F2: =SUBTOTAL(9,F4:F29) -> 3538158.9 | G2: =IFERROR(F2/D2,0) -> 1.0107014 | H2: =IFERROR(F2/E2,0) -> 1.3767184 | I2: =SUBTOTAL(9,I4:I23) -> 270973.56 | J2: =SUBTOTAL(9,J4:J29) -> 484199.8 | K2: =(F2+I2)/D2 -> 1.088107 | L2: =(F2+I2)/E2 -> 1.4821558 | M2: 46239.358
A3: REDE | B3: EQUIPE | C3: CÓD RCA | D3: META REDES | E3: META TOPS | F3: REALIZADO | G3: % REDES | H3: % TOPS | I3: A Faturar R$ | J3: Falta GAP | K3: Real + A Faturar | L3: Real + A Faturar
A4: REDE ABV | B4: 906 | C4: 507 | D4: 884542.96 | E4: 950000 | F4: =SUMIFS(redes!$F:$F,redes!$D:$D,'Top Redes'!A4) -> 1095922.4 | G4: =IFERROR(F4/D4,0) -> 1.2389702 | H4: =IFERROR(F4/E4,0) -> 1.1536025 | I4: =SUMIFS(redes!$G:$G,redes!$D:$D,'Top Redes'!A4) -> 178.56 | J4: =IF(D4-F4-I4<=0,0,D4-F4-I4) -> 0 | K4: =IFERROR((F4+I4)/E4,0) -> 1.1537905 | L4: =IFERROR((F4+I4)/D4,0) -> 1.2391721
A5: REDE VRA / MEGA | B5: 906 | C5: 721 | D5: 624018.3 | E5: 566915.45 | F5: =SUMIFS(redes!$F:$F,redes!$D:$D,'Top Redes'!A5) -> 579604.12 | G5: =IFERROR(F5/D5,0) -> 0.92882551 | H5: =IFERROR(F5/E5,0) -> 1.0223819 | I5: =SUMIFS(redes!$G:$G,redes!$D:$D,'Top Redes'!A5) -> 1607.04 | J5: =IF(D5-F5-I5<=0,0,D5-F5-I5) -> 42807.142 | K5: =IFERROR((F5+I5)/E5,0) -> 1.0252167 | L5: =IFERROR((F5+I5)/D5,0) -> 0.93140082
A6: REDE PIRES | B6: 906 | C6: 202 | D6: 406248.89 | E6: 106400.08 | F6: =SUMIFS(redes!$F:$F,redes!$D:$D,'Top Redes'!A6) -> 328342.09 | G6: =IFERROR(F6/D6,0) -> 0.8082289 | H6: =IFERROR(F6/E6,0) -> 3.0859196 | I6: =SUMIFS(redes!$G:$G,redes!$D:$D,'Top Redes'!A6) -> 0 | J6: =IF(D6-F6-I6<=0,0,D6-F6-I6) -> 77906.797 | K6: =IFERROR((F6+I6)/E6,0) -> 3.0859196 | L6: =IFERROR((F6+I6)/D6,0) -> 0.8082289
A7: REDE CIDADE BRANCA (QUADRI) | B7: 902 | C7: 714 | D7: 132472.23 | E7: 149533.32 | F7: =SUMIFS(redes!$F:$F,redes!$D:$D,'Top Redes'!A7) -> 76993.12 | G7: =IFERROR(F7/D7,0) -> 0.58120198 | H7: =IFERROR(F7/E7,0) -> 0.51488939 | I7: =SUMIFS(redes!$G:$G,redes!$D:$D,'Top Redes'!A7) -> 0 | J7: =IF(D7-F7-I7<=0,0,D7-F7-I7) -> 55479.106 | K7: =IFERROR((F7+I7)/E7,0) -> 0.51488939 | L7: =IFERROR((F7+I7)/D7,0) -> 0.58120198
A8: REDE NOVA ESTRELA | B8: 906 | C8: 211 | D8: 335377.66 | E8: 209584.19 | F8: =SUMIFS(redes!$F:$F,redes!$D:$D,'Top Redes'!A8) -> 234458.93 | G8: =IFERROR(F8/D8,0) -> 0.69908929 | H8: =IFERROR(F8/E8,0) -> 1.1186862 | I8: =SUMIFS(redes!$G:$G,redes!$D:$D,'Top Redes'!A8) -> 714.24 | J8: =IF(D8-F8-I8<=0,0,D8-F8-I8) -> 100204.49 | K8: =IFERROR((F8+I8)/E8,0) -> 1.1220941 | L8: =IFERROR((F8+I8)/D8,0) -> 0.70121895
A9: REDE SOL - ANDRE RICARDO | B9: 906 | C9: 507 | D9: 160890.06 | E9: 137621.69 | F9: =SUMIFS(redes!$F:$F,redes!$D:$D,'Top Redes'!A9) -> 218408.82 | G9: =IFERROR(F9/D9,0) -> 1.3575035 | H9: =IFERROR(F9/E9,0) -> 1.5870233 | I9: =SUMIFS(redes!$G:$G,redes!$D:$D,'Top Redes'!A9) -> 5986.12 | J9: =IF(D9-F9-I9<=0,0,D9-F9-I9) -> 0 | K9: =IFERROR((F9+I9)/E9,0) -> 1.6305202 | L9: =IFERROR((F9+I9)/D9,0) -> 1.3947098
A10: REDE NUNES | B10: 906 | C10: 702 | D10: 81473.54 | E10: 76001.987 | F10: =SUMIFS(redes!$F:$F,redes!$D:$D,'Top Redes'!A10) -> 114704.09 | G10: =IFERROR(F10/D10,0) -> 1.4078692 | H10: =IFERROR(F10/E10,0) -> 1.5092249 | I10: =SUMIFS(redes!$G:$G,redes!$D:$D,'Top Redes'!A10) -> 35827.92 | J10: =IF(D10-F10-I10<=0,0,D10-F10-I10) -> 0 | K10: =IFERROR((F10+I10)/E10,0) -> 1.9806326 | L10: =IFERROR((F10+I10)/D10,0) -> 1.8476184
A11: REDE DAMASCENO-PORTAL/PRINCESA | B11: 902 | C11: 703 | D11: 119452.2 | E11: 37318.624 | F11: =SUMIFS(redes!$F:$F,redes!$D:$D,'Top Redes'!A11) -> 136574.5 | G11: =IFERROR(F11/D11,0) -> 1.1433401 | H11: =IFERROR(F11/E11,0) -> 3.6596874 | I11: =SUMIFS(redes!$G:$G,redes!$D:$D,'Top Redes'!A11) -> 42877.97 | J11: =IF(D11-F11-I11<=0,0,D11-F11-I11) -> 0 | K11: =IFERROR((F11+I11)/E11,0) -> 4.8086571 | L11: =IFERROR((F11+I11)/D11,0) -> 1.5022952
A12: REDE JCHAGAS - FOGO/CHAMA | B12: 910 | C12: 718 | D12: 58236.697 | E12: 0 | F12: =SUMIFS(redes!$F:$F,redes!$D:$D,'Top Redes'!A12) -> 131593.66 | G12: =IFERROR(F12/D12,0) -> 2.2596347 | H12: =IFERROR(F12/E12,0) -> 0 | I12: =SUMIFS(redes!$G:$G,redes!$D:$D,'Top Redes'!A12) -> 150067.11 | J12: =IF(D12-F12-I12<=0,0,D12-F12-I12) -> 0 | K12: =IFERROR((F12+I12)/E12,0) -> 0 | L12: =IFERROR((F12+I12)/D12,0) -> 4.8364826
A13: REDEMS UNIBEM | B13: 902 | C13: 708 | D13: 52298.332 | E13: 52781.349 | F13: =SUMIFS(redes!$F:$F,redes!$D:$D,'Top Redes'!A13) -> 54084.81 | G13: =IFERROR(F13/D13,0) -> 1.0341594 | H13: =IFERROR(F13/E13,0) -> 1.0246955 | I13: =SUMIFS(redes!$G:$G,redes!$D:$D,'Top Redes'!A13) -> 2443.72 | J13: =IF(D13-F13-I13<=0,0,D13-F13-I13) -> 0 | K13: =IFERROR((F13+I13)/E13,0) -> 1.0709944 | L13: =IFERROR((F13+I13)/D13,0) -> 1.0808859
A14: REDE SUPER VALE | B14: 902 | C14: 709 | D14: 47842.231 | E14: 0 | F14: =SUMIFS(redes!$F:$F,redes!$D:$D,'Top Redes'!A14) -> 0 | G14: =IFERROR(F14/D14,0) -> 0 | H14: =IFERROR(F14/E14,0) -> 0 | I14: =SUMIFS(redes!$G:$G,redes!$D:$D,'Top Redes'!A14) -> 0 | J14: =IF(D14-F14-I14<=0,0,D14-F14-I14) -> 47842.231 | K14: =IFERROR((F14+I14)/E14,0) -> 0 | L14: =IFERROR((F14+I14)/D14,0) -> 0
A15: REDE ATLANTICO | B15: 902 | C15: 703 | D15: 53050.67 | E15: 51861.46 | F15: =SUMIFS(redes!$F:$F,redes!$D:$D,'Top Redes'!A15) -> 69939.55 | G15: =IFERROR(F15/D15,0) -> 1.3183537 | H15: =IFERROR(F15/E15,0) -> 1.3485843 | I15: =SUMIFS(redes!$G:$G,redes!$D:$D,'Top Redes'!A15) -> 29397.13 | J15: =IF(D15-F15-I15<=0,0,D15-F15-I15) -> 0 | K15: =IFERROR((F15+I15)/E15,0) -> 1.9154239 | L15: =IFERROR((F15+I15)/D15,0) -> 1.8724868
... A25: REDE MACAUBA | B25: 910 | C25: 704 | D25: 56115.084 | E25: 50653.305 | F25: =SUMIFS(redes!$F:$F,redes!$D:$D,'Top Redes'!A25) -> 29843.55 | G25: =IFERROR(F25/D25,0) -> 0.5318276 | H25: =IFERROR(F25/E25,0) -> 0.58917281 | I25: =SUMIFS(redes!$G:$G,redes!$D:$D,'Top Redes'!A25) -> 0 | J25: =IF(D25-F25-I25<=0,0,D25-F25-I25) -> 26271.534 | K25: =IFERROR((F25+I25)/E25,0) -> 0.58917281 | L25: =IFERROR((F25+I25)/D25,0) -> 0.5318276

Sheet 12.326
A1: PEDIDO.SETOR | B1: PEDIDO | C1: RAZÃO | D1: CNPJ | E1: MARGEM | F1: CFOP | G1: PORTADOR | H1: LISTA | I1: SALDO DMC | J1: TROCAS | K1: TOTAL PEDIDO | L1: PRAZOS | M1: SITUAÇÃO | N1: DIG IMP | O1: PROGRAMADO | P1: P.BRUTO | Q1: SETOR | R1: USUARIO | S1: REG | T1: QTD CX | U1: CIDADE | V1: MOV
A2: =OFFSET(hoje12_326_sp8,1,1,1,1)&"."&OFFSET(hoje12_326_sp8,1,16,1,1) -> 1067.135 | B2: 1067 | C2: CORREA MERC E COM VAR | D2: 7691695000144 | E2: 32,29 | F2: 51234 | G2: BANCO ITAU | H2: 08 | I2: 5,14- | J2: 0,00 | K2: 451.56 | L2: 007 014 000 | M2: ***** | N2: 23/07/26 | O2: 30/07/26 | P2: 38,36 | Q2: 135 | R2: kuba | S2: 002 | T2: 00071 | U2: CAMPO GRANDE | V2: I
A3: =OFFSET(hoje12_326_sp8,2,1,1,1)&"."&OFFSET(hoje12_326_sp8,2,16,1,1) -> 211001.211 | B3: 211001 | C3: NOVA ESTRELA COM DE A | D3: 12887219000303 | E3: 30,46 | F3: 51201 | G3: BANCO ITAU | H3: 08 | I3: 0,00 | J3: 0,00 | K3: 178.56 | L3: 035 000 000 | M3: 2-LIB | N3: 29/07/26 | O3: 30/07/26 | P3: 2,37 | Q3: 211 | R3: vinicius | S3: 305 | T3: 00012 | U3: TRES LAGOAS | V3: A
A4: =OFFSET(hoje12_326_sp8,3,1,1,1)&"."&OFFSET(hoje12_326_sp8,3,16,1,1) -> 211002.211 | B4: 211002 | C4: NOVA ESTRELA COMERCIO | D4: 12887219000567 | E4: 30,46 | F4: 51201 | G4: BANCO ITAU | H4: 08 | I4: 0,00 | J4: 0,00 | K4: 178.56 | L4: 035 000 000 | M4: 2-LIB | N4: 29/07/26 | O4: 30/07/26 | P4: 2,37 | Q4: 211 | R4: vinicius | S4: 306 | T4: 00012 | U4: TRES LAGOAS | V4: A
A5: =OFFSET(hoje12_326_sp8,4,1,1,1)&"."&OFFSET(hoje12_326_sp8,4,16,1,1) -> 211003.211 | B5: 211003 | C5: NOVA ESTRELA COM DE A | D5: 12887219000214 | E5: 30,46 | F5: 51201 | G5: BANCO ITAU | H5: 08 | I5: 0,00 | J5: 0,00 | K5: 178.56 | L5: 035 000 000 | M5: 2-LIB | N5: 29/07/26 | O5: 30/07/26 | P5: 2,37 | Q5: 211 | R5: vinicius | S5: 304 | T5: 00012 | U5: TRES LAGOAS | V5: A
A6: =OFFSET(hoje12_326_sp8,5,1,1,1)&"."&OFFSET(hoje12_326_sp8,5,16,1,1) -> 211004.211 | B6: 211004 | C6: NOVA ESTRELA COM DE A | D6: 12887219000133 | E6: 30,46 | F6: 51201 | G6: BANCO ITAU | H6: 08 | I6: 0,00 | J6: 0,00 | K6: 178.56 | L6: 035 000 000 | M6: 2-LIB | N6: 29/07/26 | O6: 30/07/26 | P6: 2,37 | Q6: 211 | R6: vinicius | S6: 303 | T6: 00012 | U6: TRES LAGOAS | V6: A
A7: =OFFSET(hoje12_326_sp8,6,1,1,1)&"."&OFFSET(hoje12_326_sp8,6,16,1,1) -> 600.507 | B7: 600 | C7: A R S SUPERMERCADOS L | D7: 20335148000275 | E7: 25,22 | F7: 51201 | G7: BANCO ITAU | H7: 08 | I7: 38,74- | J7: 0,00 | K7: 2814.5 | L7: 028 035 042 | M7: 2-LIB | N7: 30/07/26 | O7: 30/07/26 | P7: 34,41 | Q7: 507 | R7: kuba | S7: 320 | T7: 00204 | U7: PONTA PORA | V7: A
A8: =OFFSET(hoje12_326_sp8,7,1,1,1)&"."&OFFSET(hoje12_326_sp8,7,16,1,1) -> 601.507 | B8: 601 | C8: A R S SUPERMERCADOS L | D8: 20335148000194 | E8: 25,22 | F8: 51201 | G8: BANCO ITAU | H8: 08 | I8: 38,74- | J8: 0,00 | K8: 2814.5 | L8: 028 035 042 | M8: 2-LIB | N8: 30/07/26 | O8: 30/07/26 | P8: 34,41 | Q8: 507 | R8: kuba | S8: 320 | T8: 00204 | U8: PONTA PORA | V8: A
A9: =OFFSET(hoje12_326_sp8,8,1,1,1)&"."&OFFSET(hoje12_326_sp8,8,16,1,1) -> 507001.507 | B9: 507001 | C9: A R S SUPERMERCADOS L | D9: 20335148000194 | E9: 30,46 | F9: 51201 | G9: BANCO ITAU | H9: 08 | I9: 0,00 | J9: 0,00 | K9: 178.56 | L9: 035 000 000 | M9: 2-LIB | N9: 29/07/26 | O9: 30/07/26 | P9: 2,37 | Q9: 507 | R9: vinicius | S9: 320 | T9: 00012 | U9: PONTA PORA | V9: A
A10: =OFFSET(hoje12_326_sp8,9,1,1,1)&"."&OFFSET(hoje12_326_sp8,9,16,1,1) -> 507002.507 | B10: 507002 | C10: A R S SUPERMERCADOS L | D10: 20335148000275 | E10: 30,46 | F10: 51201 | G10: BANCO ITAU | H10: 08 | I10: 0,00 | J10: 0,00 | K10: 178.56 | L10: 035 000 000 | M10: 2-LIB | N10: 29/07/26 | O10: 30/07/26 | P10: 2,37 | Q10: 507 | R10: vinicius | S10: 320 | T10: 00012 | U10: PONTA PORA | V10: A
A11: =OFFSET(hoje12_326_sp8,10,1,1,1)&"."&OFFSET(hoje12_326_sp8,10,16,1,1) -> 507003.507 | B11: 507003 | C11: CD-00 ABV COMERCIO DE | D11: 4757459000519 | E11: 30,46 | F11: 51201 | G11: BANCO ITAU | H11: 08 | I11: 0,00 | J11: 0,00 | K11: 178.56 | L11: 039 000 000 | M11: 2-LIB | N11: 29/07/26 | O11: 30/07/26 | P11: 2,37 | Q11: 507 | R11: vinicius | S11: 336 | T11: 00012 | U11: DOURADOS | V11: A
A12: =OFFSET(hoje12_326_sp8,11,1,1,1)&"."&OFFSET(hoje12_326_sp8,11,16,1,1) -> 1240.702 | B12: 1240 | C12: SUPERMERCADO GAUCHAO | D12: 35831943000140 | E12: 22,07 | F12: 51201 | G12: BANCO ITAU | H12: 08 | I12: 43,02- | J12: 0,00 | K12: 790.72 | L12: 028 000 000 | M12: 2-LIB | N12: 30/07/26 | O12: 30/07/26 | P12: 16,60 | Q12: 702 | R12: willian | S12: 418 | T12: 00077 | U12: CAMPO GRANDE | V12: A
A13: =OFFSET(hoje12_326_sp8,12,1,1,1)&"."&OFFSET(hoje12_326_sp8,12,16,1,1) -> 1241.702 | B13: 1241 | C13: SUPERMERCADO GAUCHAO | D13: 35831943000302 | E13: 22,07 | F13: 51201 | G13: BANCO ITAU | H13: 08 | I13: 43,02- | J13: 0,00 | K13: 790.72 | L13: 028 000 000 | M13: 2-LIB | N13: 30/07/26 | O13: 30/07/26 | P13: 16,60 | Q13: 702 | R13: willian | S13: 418 | T13: 00077 | U13: CAMPO GRANDE | V13: A
A14: =OFFSET(hoje12_326_sp8,13,1,1,1)&"."&OFFSET(hoje12_326_sp8,13,16,1,1) -> 1242.702 | B14: 1242 | C14: SUPERMERCADO GAUCHAO | D14: 35831943000493 | E14: 22,07 | F14: 51201 | G14: BANCO ITAU | H14: 08 | I14: 43,02- | J14: 0,00 | K14: 790.72 | L14: 028 000 000 | M14: 2-LIB | N14: 30/07/26 | O14: 30/07/26 | P14: 16,60 | Q14: 702 | R14: willian | S14: 038 | T14: 00077 | U14: SIDROLANDIA | V14: A
A15: =OFFSET(hoje12_326_sp8,14,1,1,1)&"."&OFFSET(hoje12_326_sp8,14,16,1,1) -> 1243.702 | B15: 1243 | C15: SUPERMERCADO GAUCHAO | D15: 35831943000574 | E15: 22,07 | F15: 51201 | G15: BANCO ITAU | H15: 08 | I15: 43,02- | J15: 0,00 | K15: 790.72 | L15: 028 000 000 | M15: 2-LIB | N15: 30/07/26 | O15: 30/07/26 | P15: 16,60 | Q15: 702 | R15: willian | S15: 008 | T15: 00077 | U15: CAMPO GRANDE | V15: A
A16: =OFFSET(hoje12_326_sp8,15,1,1,1)&"."&OFFSET(hoje12_326_sp8,15,16,1,1) -> 1244.702 | B16: 1244 | C16: SUPERMERCADO GAUCHAO | D16: 35831943000736 | E16: 21,86 | F16: 51201 | G16: BANCO ITAU | H16: 08 | I16: 43,02- | J16: 0,00 | K16: 665.32 | L16: 028 000 000 | M16: 2-LIB | N16: 30/07/26 | O16: 30/07/26 | P16: 15,29 | Q16: 702 | R16: willian | S16: 002 | T16: 00065 | U16: CAMPO GRANDE | V16: A
A17: =OFFSET(hoje12_326_sp8,16,1,1,1)&"."&OFFSET(hoje12_326_sp8,16,16,1,1) -> 1245.702 | B17: 1245 | C17: SUPERMERCADO GAUCHAO | D17: 35831943000906 | E17: 22,30 | F17: 51201 | G17: BANCO ITAU | H17: 01 | I17: 43,02- | J17: 0,00 | K17: 853.6 | L17: 028 000 000 | M17: 2-LIB | N17: 30/07/26 | O17: 30/07/26 | P17: 16,75 | Q17: 702 | R17: willian | S17: 041 | T17: 00080 | U17: SONORA | V17: A
A18: =OFFSET(hoje12_326_sp8,17,1,1,1)&"."&OFFSET(hoje12_326_sp8,17,16,1,1) -> 1246.702 | B18: 1246 | C18: SUPERMERCADO GAUCHAO | D18: 35831943000221 | E18: 22,30 | F18: 51201 | G18: BANCO ITAU | H18: 08 | I18: 43,02- | J18: 0,00 | K18: 853.6 | L18: 028 000 000 | M18: 2-LIB | N18: 30/07/26 | O18: 30/07/26 | P18: 16,75 | Q18: 702 | R18: willian | S18: 036 | T18: 00080 | U18: NOVA ALVORADA DO SUL | V18: A
A19: =OFFSET(hoje12_326_sp8,18,1,1,1)&"."&OFFSET(hoje12_326_sp8,18,16,1,1) -> 1247.702 | B19: 1247 | C19: OLIVEIRA E CARNEIRO L | D19: 9531413001815 | E19: 24,79 | F19: 51201 | G19: BANCO ITAU | H19: 05 | I19: 2.084,44- | J19: 0,00 | K19: 52378.94 | L19: 049 000 000 | M19: 1-BLO | N19: 30/07/26 | O19: 30/07/26 | P19: 1.514,25 | Q19: 702 | R19: kuba | S19: 034 | T19: 07662 | U19: CORUMBA | V19: A
A20: =OFFSET(hoje12_326_sp8,19,1,1,1)&"."&OFFSET(hoje12_326_sp8,19,16,1,1) -> 1248.702 | B20: 1248 | C20: OLIVEIRA E CARNEIRO L | D20: 9531413000339 | E20: 26,47 | F20: 51201 | G20: BANCO ITAU | H20: 08 | I20: 608,21- | J20: 0,00 | K20: 10134.23 | L20: 035 000 000 | M20: 1-BLO | N20: 30/07/26 | O20: 30/07/26 | P20: 290,10 | Q20: 702 | R20: kuba | S20: 428 | T20: 01995 | U20: CAMPO GRANDE | V20: A
A21: =OFFSET(hoje12_326_sp8,20,1,1,1)&"."&OFFSET(hoje12_326_sp8,20,16,1,1) -> 1249.702 | B21: 1249 | C21: OLIVEIRA E CARNEIRO L | D21: 9531413001491 | E21: 27,15 | F21: 51201 | G21: BANCO ITAU | H21: 08 | I21: 125,73- | J21: 0,00 | K21: 3860.85 | L21: 035 000 000 | M21: 2-LIB | N21: 30/07/26 | O21: 30/07/26 | P21: 140,11 | Q21: 702 | R21: kuba | S21: 002 | T21: 00640 | U21: CAMPO GRANDE | V21: A
A22: =OFFSET(hoje12_326_sp8,21,1,1,1)&"."&OFFSET(hoje12_326_sp8,21,16,1,1) -> 1250.702 | B22: 1250 | C22: OLIVEIRA E CARNEIRO L | D22: 9531413001068 | E22: 27,17 | F22: 51201 | G22: BANCO ITAU | H22: 08 | I22: 109,85- | J22: 0,00 | K22: 3621.15 | L22: 035 000 000 | M22: 1-BLO | N22: 30/07/26 | O22: 30/07/26 | P22: 96,36 | Q22: 702 | R22: kuba | S22: 413 | T22: 00566 | U22: TERENOS | V22: A
A23: =OFFSET(hoje12_326_sp8,22,1,1,1)&"."&OFFSET(hoje12_326_sp8,22,16,1,1) -> 1251.702 | B23: 1251 | C23: OLIVEIRA E CARNEIRO L | D23: 9531413000258 | E23: 24,05 | F23: 51201 | G23: BANCO ITAU | H23: 08 | I23: 90,48- | J23: 0,00 | K23: 1207.44 | L23: 035 000 000 | M23: 1-BLO | N23: 30/07/26 | O23: 30/07/26 | P23: 36,08 | Q23: 702 | R23: kuba | S23: 004 | T23: 00262 | U23: CAMPO GRANDE | V23: A
A24: =OFFSET(hoje12_326_sp8,23,1,1,1)&"."&OFFSET(hoje12_326_sp8,23,16,1,1) -> 1252.702 | B24: 1252 | C24: OLIVEIRA E CARNEIRO L | D24: 9531413000762 | E24: 25,07 | F24: 51201 | G24: BANCO ITAU | H24: 08 | I24: 221,42- | J24: 0,00 | K24: 3681.46 | L24: 035 000 000 | M24: 1-BLO | N24: 30/07/26 | O24: 30/07/26 | P24: 108,98 | Q24: 702 | R24: kuba | S24: 004 | T24: 00639 | U24: CAMPO GRANDE | V24: A
A25: =OFFSET(hoje12_326_sp8,24,1,1,1)&"."&OFFSET(hoje12_326_sp8,24,16,1,1) -> 1254.702 | B25: 1254 | C25: OLIVEIRA E CARNEIRO L | D25: 9531413000681 | E25: 30,28 | F25: 51201 | G25: BANCO ITAU | H25: 08 | I25: 19,54- | J25: 0,00 | K25: 1102.68 | L25: 035 000 000 | M25: 1-BLO | N25: 30/07/26 | O25: 30/07/26 | P25: 20,53 | Q25: 702 | R25: kuba | S25: 006 | T25: 00152 | U25: CAMPO GRANDE | V25: A
A26: =OFFSET(hoje12_326_sp8,25,1,1,1)&"."&OFFSET(hoje12_326_sp8,25,16,1,1) -> 1255.702 | B26: 1255 | C26: OLIVEIRA E CARNEIRO L | D26: 9531413001220 | E26: 24,95 | F26: 51201 | G26: BANCO ITAU | H26: 08 | I26: 164,38- | J26: 0,00 | K26: 2215.04 | L26: 035 000 000 | M26: 2-LIB | N26: 30/07/26 | O26: 30/07/26 | P26: 50,04 | Q26: 702 | R26: kuba | S26: 427 | T26: 00382 | U26: CAMPO GRANDE | V26: A
A27: =OFFSET(hoje12_326_sp8,26,1,1,1)&"."&OFFSET(hoje12_326_sp8,26,16,1,1) -> 1256.702 | B27: 1256 | C27: OLIVEIRA E CARNEIRO L | D27: 9531413001300 | E27: 28,54 | F27: 51201 | G27: BANCO ITAU | H27: 08 | I27: 85,52- | J27: 0,00 | K27: 4175.43 | L27: 035 000 000 | M27: 1-BLO | N27: 30/07/26 | O27: 30/07/26 | P27: 107,34 | Q27: 702 | R27: kuba | S27: 010 | T27: 00539 | U27: CAMPO GRANDE | V27: A
A28: =OFFSET(hoje12_326_sp8,27,1,1,1)&"."&OFFSET(hoje12_326_sp8,27,16,1,1) -> 1257.702 | B28: 1257 | C28: OLIVEIRA E CARNEIRO L | D28: 9531413000177 | E28: 26,66 | F28: 51201 | G28: BANCO ITAU | H28: 08 | I28: 175,48- | J28: 0,00 | K28: 3000.47 | L28: 035 000 000 | M28: 1-BLO | N28: 30/07/26 | O28: 30/07/26 | P28: 95,10 | Q28: 702 | R28: kuba | S28: 004 | T28: 00687 | U28: CAMPO GRANDE | V28: A
A29: =OFFSET(hoje12_326_sp8,28,1,1,1)&"."&OFFSET(hoje12_326_sp8,28,16,1,1) -> 1258.702 | B29: 1258 | C29: OLIVEIRA E CARNEIRO L | D29: 9531413000410 | E29: 25,81 | F29: 51201 | G29: BANCO ITAU | H29: 08 | I29: 161,16- | J29: 0,00 | K29: 2829.17 | L29: 035 000 000 | M29: 1-BLO | N29: 30/07/26 | O29: 30/07/26 | P29: 84,90 | Q29: 702 | R29: kuba | S29: 010 | T29: 00505 | U29: CAMPO GRANDE | V29: A
A30: =OFFSET(hoje12_326_sp8,29,1,1,1)&"."&OFFSET(hoje12_326_sp8,29,16,1,1) -> 702001.702 | B30: 702001 | C30: SUPERMERCADO GAUCHAO | D30: 35831943000655 | E30: 30,46 | F30: 51201 | G30: BANCO ITAU | H30: 08 | I30: 0,00 | J30: 0,00 | K30: 178.56 | L30: 028 000 000 | M30: 2-LIB | N30: 29/07/26 | O30: 30/07/26 | P30: 2,37 | Q30: 702 | R30: vinicius | S30: 418 | T30: 00012 | U30: CAMPO GRANDE | V30: A
A31: =OFFSET(hoje12_326_sp8,30,1,1,1)&"."&OFFSET(hoje12_326_sp8,30,16,1,1) -> 2406.703 | B31: 2406 | C31: DAMASCENO E DAMASCENO | D31: 1274396000390 | E31: 14,36 | F31: 51201 | G31: BANCO ITAU | H31: 08 | I31: 337,76- | J31: 0,00 | K31: 2092.12 | L31: 028 000 000 | M31: 2-LIB | N31: 23/07/26 | O31: 30/07/26 | P31: 79,34 | Q31: 703 | R31: willian | S31: 330 | T31: 00204 | U31: AQUIDAUANA | V31: A
A32: =OFFSET(hoje12_326_sp8,31,1,1,1)&"."&OFFSET(hoje12_326_sp8,31,16,1,1) -> 2407.703 | B32: 2407 | C32: DAMASCENO E DAMASCENO | D32: 1274396000209 | E32: 14,47 | F32: 51201 | G32: BANCO ITAU | H32: 08 | I32: 367,71- | J32: 0,00 | K32: 2261.91 | L32: 028 000 000 | M32: 2-LIB | N32: 23/07/26 | O32: 30/07/26 | P32: 85,20 | Q32: 703 | R32: willian | S32: 330 | T32: 00243 | U32: ANASTACIO | V32: A
A33: =OFFSET(hoje12_326_sp8,32,1,1,1)&"."&OFFSET(hoje12_326_sp8,32,16,1,1) -> 2408.703 | B33: 2408 | C33: DAMASCENO E DAMASCENO | D33: 1274396000632 | E33: 11,01 | F33: 51201 | G33: BANCO ITAU | H33: 08 | I33: 1.009,96- | J33: 0,00 | K33: 5755.34 | L33: 028 000 000 | M33: 2-LIB | N33: 23/07/26 | O33: 30/07/26 | P33: 259,14 | Q33: 703 | R33: willian | S33: 330 | T33: 00666 | U33: ANASTACIO | V33: A
A34: =OFFSET(hoje12_326_sp8,33,1,1,1)&"."&OFFSET(hoje12_326_sp8,33,16,1,1) -> 2409.703 | B34: 2409 | C34: DAMASCENO E DAMASCENO | D34: 1274396000713 | E34: 14,90 | F34: 51201 | G34: BANCO ITAU | H34: 08 | I34: 300,15- | J34: 0,00 | K34: 1878.93 | L34: 028 000 000 | M34: 2-LIB | N34: 23/07/26 | O34: 30/07/26 | P34: 76,73 | Q34: 703 | R34: willian | S34: 331 | T34: 00180 | U34: MIRANDA | V34: A
A35: =OFFSET(hoje12_326_sp8,34,1,1,1)&"."&OFFSET(hoje12_326_sp8,34,16,1,1) -> 2410.703 | B35: 2410 | C35: DAMASCENO E DAMASCENO | D35: 1274396000802 | E35: 14,48 | F35: 51201 | G35: BANCO ITAU | H35: 08 | I35: 372,60- | J35: 0,00 | K35: 2248.86 | L35: 028 000 000 | M35: 2-LIB | N35: 23/07/26 | O35: 30/07/26 | P35: 88,57 | Q35: 703 | R35: willian | S35: 039 | T35: 00267 | U35: CHAPADAO DO SUL | V35: A
A36: =OFFSET(hoje12_326_sp8,35,1,1,1)&"."&OFFSET(hoje12_326_sp8,35,16,1,1) -> 2412.703 | B36: 2412 | C36: DAMASCENO E DAMASCENO | D36: 1274396001019 | E36: 11,77 | F36: 51201 | G36: BANCO ITAU | H36: 08 | I36: 668,89- | J36: 0,00 | K36: 3849.11 | L36: 028 000 000 | M36: 2-LIB | N36: 23/07/26 | O36: 30/07/26 | P36: 179,74 | Q36: 703 | R36: willian | S36: 330 | T36: 00432 | U36: AQUIDAUANA | V36: A
A37: =OFFSET(hoje12_326_sp8,36,1,1,1)&"."&OFFSET(hoje12_326_sp8,36,16,1,1) -> 2413.703 | B37: 2413 | C37: DAMASCENO E DAMASCENO | D37: 1274396000985 | E37: 12,18 | F37: 51201 | G37: BANCO ITAU | H37: 08 | I37: 618,42- | J37: 0,00 | K37: 3360.54 | L37: 028 000 000 | M37: 2-LIB | N37: 23/07/26 | O37: 30/07/26 | P37: 157,51 | Q37: 703 | R37: willian | S37: 331 | T37: 00510 | U37: MIRANDA | V37: A
A38: =OFFSET(hoje12_326_sp8,37,1,1,1)&"."&OFFSET(hoje12_326_sp8,37,16,1,1) -> 2416.703 | B38: 2416 | C38: BATISTA QUADROS E CIA | D38: 5348350000167 | E38: 12,17 | F38: 51201 | G38: BANCO ITAU | H38: 08 | I38: 369,94- | J38: 0,00 | K38: 1701.86 | L38: 028 000 000 | M38: 2-LIB | N38: 23/07/26 | O38: 30/07/26 | P38: 61,50 | Q38: 703 | R38: willian | S38: 033 | T38: 00168 | U38: AQUIDAUANA | V38: A
A39: =OFFSET(hoje12_326_sp8,38,1,1,1)&"."&OFFSET(hoje12_326_sp8,38,16,1,1) -> 2417.703 | B39: 2417 | C39: BATISTA QUADROS E CIA | D39: 5348350000248 | E39: 15,36 | F39: 51201 | G39: BANCO ITAU | H39: 08 | I39: 288,62- | J39: 0,00 | K39: 1678.18 | L39: 028 000 000 | M39: 2-LIB | N39: 23/07/26 | O39: 30/07/26 | P39: 49,95 | Q39: 703 | R39: willian | S39: 033 | T39: 00162 | U39: AQUIDAUANA | V39: A
A40: =OFFSET(hoje12_326_sp8,39,1,1,1)&"."&OFFSET(hoje12_326_sp8,39,16,1,1) -> 2418.703 | B40: 2418 | C40: BATISTA QUADROS E CIA | D40: 5348350000329 | E40: 15,63 | F40: 51201 | G40: BANCO ITAU | H40: 08 | I40: 407,65- | J40: 0,00 | K40: 2429.87 | L40: 028 000 000 | M40: 2-LIB | N40: 23/07/26 | O40: 30/07/26 | P40: 87,17 | Q40: 703 | R40: willian | S40: 033 | T40: 00276 | U40: ANASTACIO | V40: A
...

Sheet 319
A1: RANK | B1: CNPJ | C1: RAZÃO SOCIAL | D1: CIDADE | E1: ENDEREÇO | F1: PESO BRUTO | G1: CAIXA | H1: VALOR | I1: %PB | J1: %CX | K1: %VLR | L1: %ACP | M1: %ACG | N1: REP | O1: PR MED | P1: CENSO | Q1: =SUM(H:H) -> 4600515 | R1: =COUNT(A:A) -> 761 | S1: =SUBTOTAL(9,H:H) -> 4600515
A2: 1 | B2: 4757459000519 | C2: CD-00 ABV COMERCIO DE AL | D2: DOURADOS | E2: SALETE TEREZINHA HAR | F2: 32505 | G2: 5516 | H2: 1097650.1 | I2: 23.4 | J2: 23.32 | K2: 23.85 | L2: 23.85 | M2: 23.85 | N2: 507 | O2: 0 | P2: A36
A3: 2 | B3: 2318826000200 | C3: VRA COMERCIO LTDA | D3: CORUMBA | E3: PEDRO DE MEDEIROS | F3: 6811 | G3: 874 | H3: 221339.41 | I3: 4.9 | J3: 3.69 | K3: 4.81 | L3: 28.67 | M3: 28.67 | N3: 721 | O3: 0 | P3: A03
A4: 3 | B4: 4822179000113 | C4: CENTRAL ECONOMICA DE DIS | D4: CAMPO GRANDE | E4: AV DOUTOR GUNTER HAN | F4: 6245 | G4: 900 | H4: 175918.17 | I4: 4.49 | J4: 3.8 | K4: 3.82 | L4: 32.49 | M4: 32.49 | N4: 301 | O4: 0 | P4: A15
A5: 4 | B5: 20335148000194 | C5: A R S SUPERMERCADOS LTDA | D5: PONTA PORA | E5: BRASIL | F5: 2980 | G5: 651 | H5: 113356.7 | I5: 2.14 | J5: 2.75 | K5: 2.46 | L5: 34.95 | M5: 34.95 | N5: 507 | O5: 0 | P5: A35
A6: 5 | B6: 20335148000275 | C6: A R S SUPERMERCADOS LTDA | D6: PONTA PORA | E6: AV URUMBELA | F6: 5456 | G6: 575 | H6: 105295.06 | I6: 3.92 | J6: 2.43 | K6: 2.28 | L6: 37.24 | M6: 37.24 | N6: 507 | O6: 0 | P6: A35
A7: 6 | B7: 12887219000133 | C7: NOVA ESTRELA COM DE ALIM | D7: TRES LAGOAS | E7: CLODOALDO GARCIA | F7: 4425 | G7: 1278 | H7: 100366.21 | I7: 3.18 | J7: 5.4 | K7: 2.18 | L7: 39.42 | M7: 39.42 | N7: 211 | O7: 0 | P7: A35
A8: 7 | B8: 9401283000158 | C8: IYOBE E CIA LTDA | D8: PONTA PORA | E8: JORGE ROBERTO SALOMA | F8: 2681 | G8: 273 | H8: 91720.46 | I8: 1.93 | J8: 1.15 | K8: 1.99 | L8: 41.42 | M8: 41.42 | N8: 715 | O8: 0 | P8: A41
A9: 8 | B9: 2318826000633 | C9: VRA COMERCIO LTDA | D9: COSTA RICA | E9: JOSE FERREIRA DA CO | F9: 1925 | G9: 395 | H9: 84468.68 | I9: 1.38 | J9: 1.66 | K9: 1.83 | L9: 43.25 | M9: 43.25 | N9: 721 | O9: 0 | P9: A03
A10: 9 | B10: 6813685001496 | C10: JCHAGAS ALIMENTOS LTDA | D10: NAVIRAI | E10: AV CAMPO GRANDE | F10: 2231 | G10: 374 | H10: 78869.4 | I10: 1.6 | J10: 1.58 | K10: 1.71 | L10: 44.97 | M10: 44.97 | N10: 704 | O10: 0 | P10: A35
A11: 10 | B11: 12887219000214 | C11: NOVA ESTRELA COM DE ALIM | D11: TRES LAGOAS | E11: CAPITAO OLINTO MANCI | F11: 2297 | G11: 536 | H11: 66607.84 | I11: 1.65 | J11: 2.26 | K11: 1.44 | L11: 46.42 | M11: 46.42 | N11: 211 | O11: 0 | P11: A35
A12: 11 | B12: 2318826001281 | C12: VRA COMERCIO LTDA | D12: CHAPADAO DO SUL | E12: AVENIDA ALEMANHA | F12: 1621 | G12: 338 | H12: 66399.07 | I12: 1.16 | J12: 1.42 | K12: 1.44 | L12: 47.86 | M12: 47.86 | N12: 721 | O12: 0 | P12: A35
A13: 12 | B13: 2318826000390 | C13: VRA COMERCIO LTDA | D13: IVINHEMA | E13: BRASIL | F13: 1820 | G13: 358 | H13: 64515.33 | I13: 1.31 | J13: 1.51 | K13: 1.4 | L13: 49.26 | M13: 49.26 | N13: 721 | O13: 0 | P13: A03
... A762: 761 | B762: 6968830000274 | C762: MERCADO BRASIL LTDA | D762: INOCENCIA | E762: ALEXANDRE BATISTA GA | F762: -872 | G762: -115 | H762: -26324.66 | I762: -0.62 | J762: -0.48 | K762: -0.57 | L762: 100 | M762: 100 | N762: 706 | O762: 0 | P762: A15

Sheet 12.326ana
A1: Cod Prod | B1: Desc Prod | C1: Total Vlr | D1: Desc $ | E1: Qtde | F1: Vlr Und | G1: %D.Maxi | H1: %D.Pedido | I1: %DM | J1: Dif $ | K1: Nº Pedido | L1: Rep | M1: CNPJ
A2: 11100009 | B2: AJAX FDF MAR DE FLORES..........01X500ML | C2: 14.73 | D2: 0 | E2: 3 | F2: 4.91 | G2: 0,00 | H2: 0,00 | I2: 0,00 | J2: 0,00 | K2: 1067 | L2: 135 | M2: =IFERROR(VLOOKUP((OFFSET(hoje12_326_ana9,1,10,1,1)&"."&OFFSET(hoje12_326_ana9,1,11,1,1)),'12.326'!A:D,4,0),"-") -> 7691695000144
A3: 11100017 | B3: AJAX FRESH LIMAO................01X500ML | C3: 22.26 | D3: 0 | E3: 3 | F3: 7.42 | G3: 0,00 | H3: 0,00 | I3: 0,00 | J3: 0,00 | K3: 1067 | L3: 135 | M3: =IFERROR(VLOOKUP((OFFSET(hoje12_326_ana9,2,10,1,1)&"."&OFFSET(hoje12_326_ana9,2,11,1,1)),'12.326'!A:D,4,0),"-") -> 7691695000144
A4: 11100034 | B4: AJAX LIMP PERF BOUQUET FLORES...01X500ML | C4: 14.73 | D4: 0 | E4: 3 | F4: 4.91 | G4: 0,00 | H4: 0,00 | I4: 0,00 | J4: 0,00 | K4: 1067 | L4: 135 | M4: =IFERROR(VLOOKUP((OFFSET(hoje12_326_ana9,3,10,1,1)&"."&OFFSET(hoje12_326_ana9,3,11,1,1)),'12.326'!A:D,4,0),"-") -> 7691695000144
A5: 11100059 | B5: CD COLG L12 TRI 90G GT3 LUM 60G.01X 15UN | C5: 117.7 | D5: 0 | E5: 2 | F5: 58.85 | G5: 0,00 | H5: 0,00 | I5: 0,00 | J5: 0,00 | K5: 1067 | L5: 135 | M5: =IFERROR(VLOOKUP((OFFSET(hoje12_326_ana9,4,10,1,1)&"."&OFFSET(hoje12_326_ana9,4,11,1,1)),'12.326'!A:D,4,0),"-") -> 7691695000144
A6: 11100213 | B6: CD SORR DENTES BRANCOS..........01X 50GR | C6: 31.44 | D6: 0 | E6: 12 | F6: 2.62 | G6: 0,00 | H6: 0,00 | I6: 0,00 | J6: 0,00 | K6: 1067 | L6: 135 | M6: =IFERROR(VLOOKUP((OFFSET(hoje12_326_ana9,5,10,1,1)&"."&OFFSET(hoje12_326_ana9,5,11,1,1)),'12.326'!A:D,4,0),"-") -> 7691695000144
A7: 11100689 | B7: SAB PALM MELANCIA E LICHIA......01X 85GR | C7: 49.03 | D7: 2.57 | E7: 24 | F7: 2.15 | G7: 0,00 | H7: 5,00 | I7: 0,00 | J7: 2,58- | K7: 1067 | L7: 135 | M7: =IFERROR(VLOOKUP((OFFSET(hoje12_326_ana9,6,10,1,1)&"."&OFFSET(hoje12_326_ana9,6,11,1,1)),'12.326'!A:D,4,0),"-") -> 7691695000144
A8: 11100728 | B8: SAB PALM TOQ NUT FRAMB E AMORA..01X 85GR | C8: 49.03 | D8: 2.57 | E8: 24 | F8: 2.15 | G8: 0,00 | H8: 5,00 | I8: 0,00 | J8: 2,58- | K8: 1067 | L8: 135 | M8: =IFERROR(VLOOKUP((OFFSET(hoje12_326_ana9,7,10,1,1)&"."&OFFSET(hoje12_326_ana9,7,11,1,1)),'12.326'!A:D,4,0),"-") -> 7691695000144
A9: 11101000 | B9: ED COLG AD SMILES HARRY POTTER..01X 02UN | C9: 68.97 | D9: 0 | E9: 3 | F9: 22.99 | G9: 0,00 | H9: 0,00 | I9: 0,00 | J9: 0,00 | K9: 211001 | L9: 211 | M9: =IFERROR(VLOOKUP((OFFSET(hoje12_326_ana9,8,10,1,1)&"."&OFFSET(hoje12_326_ana9,8,11,1,1)),'12.326'!A:D,4,0),"-") -> 12887219000303
A10: 11100998 | B10: CD COLG LUM WHIT COLOR CORRECT..01X133GR | C10: 45.03 | D10: 0 | E10: 3 | F10: 15.01 | G10: 0,00 | H10: 0,00 | I10: 0,00 | J10: 0,00 | K10: 211001 | L10: 211 | M10: =IFERROR(VLOOKUP((OFFSET(hoje12_326_ana9,9,10,1,1)&"."&OFFSET(hoje12_326_ana9,9,11,1,1)),'12.326'!A:D,4,0),"-") -> 12887219000303
A11: 11101004 | B11: SAB LIQ CORP AMEND ABACAT LEITE.01X250ML | C11: 32.28 | D11: 0 | E11: 3 | F11: 10.76 | G11: 0,00 | H11: 0,00 | I11: 0,00 | J11: 0,00 | K11: 211001 | L11: 211 | M11: =IFERROR(VLOOKUP((OFFSET(hoje12_326_ana9,10,10,1,1)&"."&OFFSET(hoje12_326_ana9,10,11,1,1)),'12.326'!A:D,4,0),"-") -> 12887219000303
A12: 11101003 | B12: SAB LIQ CORP AMORA BANAN IOGURT.01X250ML | C12: 32.28 | D12: 0 | E12: 3 | F12: 10.76 | G12: 0,00 | H12: 0,00 | I12: 0,00 | J12: 0,00 | K12: 211001 | L12: 211 | M12: =IFERROR(VLOOKUP((OFFSET(hoje12_326_ana9,11,10,1,1)&"."&OFFSET(hoje12_326_ana9,11,11,1,1)),'12.326'!A:D,4,0),"-") -> 12887219000303
A13: 11101000 | B13: ED COLG AD SMILES HARRY POTTER..01X 02UN | C13: 68.97 | D13: 0 | E13: 3 | F13: 22.99 | G13: 0,00 | H13: 0,00 | I13: 0,00 | J13: 0,00 | K13: 211002 | L13: 211 | M13: =IFERROR(VLOOKUP((OFFSET(hoje12_326_ana9,12,10,1,1)&"."&OFFSET(hoje12_326_ana9,12,11,1,1)),'12.326'!A:D,4,0),"-") -> 12887219000567
A14: 11100998 | B14: CD COLG LUM WHIT COLOR CORRECT..01X133GR | C14: 45.03 | D14: 0 | E14: 3 | F14: 15.01 | G14: 0,00 | H14: 0,00 | I14: 0,00 | J14: 0,00 | K14: 211002 | L14: 211 | M14: =IFERROR(VLOOKUP((OFFSET(hoje12_326_ana9,13,10,1,1)&"."&OFFSET(hoje12_326_ana9,13,11,1,1)),'12.326'!A:D,4,0),"-") -> 12887219000567
A15: 11101004 | B15: SAB LIQ CORP AMEND ABACAT LEITE.01X250ML | C15: 32.28 | D15: 0 | E15: 3 | F15: 10.76 | G15: 0,00 | H15: 0,00 | I15: 0,00 | J15: 0,00 | K15: 211002 | L15: 211 | M15: =IFERROR(VLOOKUP((OFFSET(hoje12_326_ana9,14,10,1,1)&"."&OFFSET(hoje12_326_ana9,14,11,1,1)),'12.326'!A:D,4,0),"-") -> 12887219000567
A16: 11101003 | B16: SAB LIQ CORP AMORA BANAN IOGURT.01X250ML | C16: 32.28 | D16: 0 | E16: 3 | F16: 10.76 | G16: 0,00 | H16: 0,00 | I16: 0,00 | J16: 0,00 | K16: 211002 | L16: 211 | M16: =IFERROR(VLOOKUP((OFFSET(hoje12_326_ana9,15,10,1,1)&"."&OFFSET(hoje12_326_ana9,15,11,1,1)),'12.326'!A:D,4,0),"-") -> 12887219000567
A17: 11101000 | B17: ED COLG AD SMILES HARRY POTTER..01X 02UN | C17: 68.97 | D17: 0 | E17: 3 | F17: 22.99 | G17: 0,00 | H17: 0,00 | I17: 0,00 | J17: 0,00 | K17: 211003 | L17: 211 | M17: =IFERROR(VLOOKUP((OFFSET(hoje12_326_ana9,16,10,1,1)&"."&OFFSET(hoje12_326_ana9,16,11,1,1)),'12.326'!A:D,4,0),"-") -> 12887219000214
A18: 11100998 | B18: CD COLG LUM WHIT COLOR CORRECT..01X133GR | C18: 45.03 | D18: 0 | E18: 3 | F18: 15.01 | G18: 0,00 | H18: 0,00 | I18: 0,00 | J18: 0,00 | K18: 211003 | L18: 211 | M18: =IFERROR(VLOOKUP((OFFSET(hoje12_326_ana9,17,10,1,1)&"."&OFFSET(hoje12_326_ana9,17,11,1,1)),'12.326'!A:D,4,0),"-") -> 12887219000214
A19: 11101004 | B19: SAB LIQ CORP AMEND ABACAT LEITE.01X250ML | C19: 32.28 | D19: 0 | E19: 3 | F19: 10.76 | G19: 0,00 | H19: 0,00 | I19: 0,00 | J19: 0,00 | K19: 211003 | L19: 211 | M19: =IFERROR(VLOOKUP((OFFSET(hoje12_326_ana9,18,10,1,1)&"."&OFFSET(hoje12_326_ana9,18,11,1,1)),'12.326'!A:D,4,0),"-") -> 12887219000214
A20: 11101003 | B20: SAB LIQ CORP AMORA BANAN IOGURT.01X250ML | C20: 32.28 | D20: 0 | E20: 3 | F20: 10.76 | G20: 0,00 | H20: 0,00 | I20: 0,00 | J20: 0,00 | K20: 211003 | L20: 211 | M20: =IFERROR(VLOOKUP((OFFSET(hoje12_326_ana9,19,10,1,1)&"."&OFFSET(hoje12_326_ana9,19,11,1,1)),'12.326'!A:D,4,0),"-") -> 12887219000214
A21: 11101000 | B21: ED COLG AD SMILES HARRY POTTER..01X 02UN | C21: 68.97 | D21: 0 | E21: 3 | F21: 22.99 | G21: 0,00 | H21: 0,00 | I21: 0,00 | J21: 0,00 | K21: 211004 | L21: 211 | M21: =IFERROR(VLOOKUP((OFFSET(hoje12_326_ana9,20,10,1,1)&"."&OFFSET(hoje12_326_ana9,20,11,1,1)),'12.326'!A:D,4,0),"-") -> 12887219000133
A22: 11100998 | B22: CD COLG LUM WHIT COLOR CORRECT..01X133GR | C22: 45.03 | D22: 0 | E22: 3 | F22: 15.01 | G22: 0,00 | H22: 0,00 | I22: 0,00 | J22: 0,00 | K22: 211004 | L22: 211 | M22: =IFERROR(VLOOKUP((OFFSET(hoje12_326_ana9,21,10,1,1)&"."&OFFSET(hoje12_326_ana9,21,11,1,1)),'12.326'!A:D,4,0),"-") -> 12887219000133
A23: 11101004 | B23: SAB LIQ CORP AMEND ABACAT LEITE.01X250ML | C23: 32.28 | D23: 0 | E23: 3 | F23: 10.76 | G23: 0,00 | H23: 0,00 | I23: 0,00 | J23: 0,00 | K23: 211004 | L23: 211 | M23: =IFERROR(VLOOKUP((OFFSET(hoje12_326_ana9,22,10,1,1)&"."&OFFSET(hoje12_326_ana9,22,11,1,1)),'12.326'!A:D,4,0),"-") -> 12887219000133
A24: 11101003 | B24: SAB LIQ CORP AMORA BANAN IOGURT.01X250ML | C24: 32.28 | D24: 0 | E24: 3 | F24: 10.76 | G24: 0,00 | H24: 0,00 | I24: 0,00 | J24: 0,00 | K24: 211004 | L24: 211 | M24: =IFERROR(VLOOKUP((OFFSET(hoje12_326_ana9,23,10,1,1)&"."&OFFSET(hoje12_326_ana9,23,11,1,1)),'12.326'!A:D,4,0),"-") -> 12887219000133
A25: 11100987 | B25: CD COLG TT LIMP PROF INTERDENT..01X 90GR | C25: 501.6 | D25: 0 | E25: 48 | F25: 10.45 | G25: 0,00 | H25: 0,00 | I25: 0,00 | J25: 0,00 | K25: 600 | L25: 507 | M25: =IFERROR(VLOOKUP((OFFSET(hoje12_326_ana9,24,10,1,1)&"."&OFFSET(hoje12_326_ana9,24,11,1,1)),'12.326'!A:D,4,0),"-") -> 20335148000275
A26: 11100992 | B26: CD COLG TT LIMP PROF INTERDENT..01X180GR | C26: 736.8 | D26: 0 | E26: 48 | F26: 15.35 | G26: 0,00 | H26: 0,00 | I26: 0,00 | J26: 0,00 | K26: 600 | L26: 507 | M26: =IFERROR(VLOOKUP((OFFSET(hoje12_326_ana9,25,10,1,1)&"."&OFFSET(hoje12_326_ana9,25,11,1,1)),'12.326'!A:D,4,0),"-") -> 20335148000275
A27: 11100998 | B27: CD COLG LUM WHIT COLOR CORRECT..01X133GR | C27: 1080.72 | D27: 0 | E27: 72 | F27: 15.01 | G27: 0,00 | H27: 0,00 | I27: 0,00 | J27: 0,00 | K27: 600 | L27: 507 | M27: =IFERROR(VLOOKUP((OFFSET(hoje12_326_ana9,26,10,1,1)&"."&OFFSET(hoje12_326_ana9,26,11,1,1)),'12.326'!A:D,4,0),"-") -> 20335148000275
A28: 11101000 | B28: ED COLG AD SMILES HARRY POTTER..01X 02UN | C28: 275.88 | D28: 0 | E28: 12 | F28: 22.99 | G28: 0,00 | H28: 0,00 | I28: 0,00 | J28: 0,00 | K28: 600 | L28: 507 | M28: =IFERROR(VLOOKUP((OFFSET(hoje12_326_ana9,27,10,1,1)&"."&OFFSET(hoje12_326_ana9,27,11,1,1)),'12.326'!A:D,4,0),"-") -> 20335148000275
A29: 11101003 | B29: SAB LIQ CORP AMORA BANAN IOGURT.01X250ML | C29: 109.75 | D29: 19.37 | E29: 12 | F29: 10.76 | G29: 0,00 | H29: 15,00 | I29: 0,00 | J29: 19,36- | K29: 600 | L29: 507 | M29: =IFERROR(VLOOKUP((OFFSET(hoje12_326_ana9,28,10,1,1)&"."&OFFSET(hoje12_326_ana9,28,11,1,1)),'12.326'!A:D,4,0),"-") -> 20335148000275
A30: 11101004 | B30: SAB LIQ CORP AMEND ABACAT LEITE.01X250ML | C30: 109.75 | D30: 19.37 | E30: 12 | F30: 10.76 | G30: 0,00 | H30: 15,00 | I30: 0,00 | J30: 19,36- | K30: 600 | L30: 507 | M30: =IFERROR(VLOOKUP((OFFSET(hoje12_326_ana9,29,10,1,1)&"."&OFFSET(hoje12_326_ana9,29,11,1,1)),'12.326'!A:D,4,0),"-") -> 20335148000275
A31: 11100987 | B31: CD COLG TT LIMP PROF INTERDENT..01X 90GR | C31: 501.6 | D31: 0 | E31: 48 | F31: 10.45 | G31: 0,00 | H31: 0,00 | I31: 0,00 | J31: 0,00 | K31: 601 | L31: 507 | M31: =IFERROR(VLOOKUP((OFFSET(hoje12_326_ana9,30,10,1,1)&"."&OFFSET(hoje12_326_ana9,30,11,1,1)),'12.326'!A:D,4,0),"-") -> 20335148000194
A32: 11100992 | B32: CD COLG TT LIMP PROF INTERDENT..01X180GR | C32: 736.8 | D32: 0 | E32: 48 | F32: 15.35 | G32: 0,00 | H32: 0,00 | I32: 0,00 | J32: 0,00 | K32: 601 | L32: 507 | M32: =IFERROR(VLOOKUP((OFFSET(hoje12_326_ana9,31,10,1,1)&"."&OFFSET(hoje12_326_ana9,31,11,1,1)),'12.326'!A:D,4,0),"-") -> 20335148000194
A33: 11100998 | B33: CD COLG LUM WHIT COLOR CORRECT..01X133GR | C33: 1080.72 | D33: 0 | E33: 72 | F33: 15.01 | G33: 0,00 | H33: 0,00 | I33: 0,00 | J33: 0,00 | K33: 601 | L33: 507 | M33: =IFERROR(VLOOKUP((OFFSET(hoje12_326_ana9,32,10,1,1)&"."&OFFSET(hoje12_326_ana9,32,11,1,1)),'12.326'!A:D,4,0),"-") -> 20335148000194
A34: 11101000 | B34: ED COLG AD SMILES HARRY POTTER..01X 02UN | C34: 275.88 | D34: 0 | E34: 12 | F34: 22.99 | G34: 0,00 | H34: 0,00 | I34: 0,00 | J34: 0,00 | K34: 601 | L34: 507 | M34: =IFERROR(VLOOKUP((OFFSET(hoje12_326_ana9,33,10,1,1)&"."&OFFSET(hoje12_326_ana9,33,11,1,1)),'12.326'!A:D,4,0),"-") -> 20335148000194
A35: 11101003 | B35: SAB LIQ CORP AMORA BANAN IOGURT.01X250ML | C35: 109.75 | D35: 19.37 | E35: 12 | F35: 10.76 | G35: 0,00 | H35: 15,00 | I35: 0,00 | J35: 19,36- | K35: 601 | L35: 507 | M35: =IFERROR(VLOOKUP((OFFSET(hoje12_326_ana9,34,10,1,1)&"."&OFFSET(hoje12_326_ana9,34,11,1,1)),'12.326'!A:D,4,0),"-") -> 20335148000194
A36: 11101004 | B36: SAB LIQ CORP AMEND ABACAT LEITE.01X250ML | C36: 109.75 | D36: 19.37 | E36: 12 | F36: 10.76 | G36: 0,00 | H36: 15,00 | I36: 0,00 | J36: 19,36- | K36: 601 | L36: 507 | M36: =IFERROR(VLOOKUP((OFFSET(hoje12_326_ana9,35,10,1,1)&"."&OFFSET(hoje12_326_ana9,35,11,1,1)),'12.326'!A:D,4,0),"-") -> 20335148000194
A37: 11101000 | B37: ED COLG AD SMILES HARRY POTTER..01X 02UN | C37: 68.97 | D37: 0 | E37: 3 | F37: 22.99 | G37: 0,00 | H37: 0,00 | I37: 0,00 | J37: 0,00 | K37: 507001 | L37: 507 | M37: =IFERROR(VLOOKUP((OFFSET(hoje12_326_ana9,36,10,1,1)&"."&OFFSET(hoje12_326_ana9,36,11,1,1)),'12.326'!A:D,4,0),"-") -> 20335148000194
A38: 11100998 | B38: CD COLG LUM WHIT COLOR CORRECT..01X133GR | C38: 45.03 | D38: 0 | E38: 3 | F38: 15.01 | G38: 0,00 | H38: 0,00 | I38: 0,00 | J38: 0,00 | K38: 507001 | L38: 507 | M38: =IFERROR(VLOOKUP((OFFSET(hoje12_326_ana9,37,10,1,1)&"."&OFFSET(hoje12_326_ana9,37,11,1,1)),'12.326'!A:D,4,0),"-") -> 20335148000194
A39: 11101004 | B39: SAB LIQ CORP AMEND ABACAT LEITE.01X250ML | C39: 32.28 | D39: 0 | E39: 3 | F39: 10.76 | G39: 0,00 | H39: 0,00 | I39: 0,00 | J39: 0,00 | K39: 507001 | L39: 507 | M39: =IFERROR(VLOOKUP((OFFSET(hoje12_326_ana9,38,10,1,1)&"."&OFFSET(hoje12_326_ana9,38,11,1,1)),'12.326'!A:D,4,0),"-") -> 20335148000194
A40: 11101003 | B40: SAB LIQ CORP AMORA BANAN IOGURT.01X250ML | C40: 32.28 | D40: 0 | E40: 3 | F40: 10.76 | G40: 0,00 | H40: 0,00 | I40: 0,00 | J40: 0,00 | K40: 507001 | L40: 507 | M40: =IFERROR(VLOOKUP((OFFSET(hoje12_326_ana9,39,10,1,1)&"."&OFFSET(hoje12_326_ana9,39,11,1,1)),'12.326'!A:D,4,0),"-") -> 20335148000194
...

Sheet Loja a Loja
F1: =SUBTOTAL(9,F3:F886) -> 50037180 | G1: =SUBTOTAL(9,G3:G886) -> 3438308.1
A2: CNPJ | B2: Razao | C2: Rede | D2: Fantasia | E2: Cidade | F2: META | G2: REALIZADO
A3: 1274396000128 | B3: DAMASCENO E DAMASCENO LTDA | C3: REDE DAMASCENO-PORTAL/PRINCESA | D3: SUPERMERCADOS PRINCESA I | E3: AQUIDAUANA | F3: =VLOOKUP(C3,'Top Redes'!A:D,4,0) -> 119452.2 | G3: =IFERROR(VLOOKUP($A3,'319'!$B:$H,7,0),0) -> 2692.15
A4: 1274396000209 | B4: DAMASCENO E DAMASCENO LTDA | C4: REDE DAMASCENO-PORTAL/PRINCESA | D4: SUPERMERCADOS PRINCESAS II | E4: ANASTACIO | F4: =VLOOKUP(C4,'Top Redes'!A:D,4,0) -> 119452.2 | G4: =IFERROR(VLOOKUP($A4,'319'!$B:$H,7,0),0) -> 4037.09
A5: 1274396000390 | B5: DAMASCENO E DAMASCENO LTDA | C5: REDE DAMASCENO-PORTAL/PRINCESA | D5: SM PRINCESA III | E5: AQUIDAUANA | F5: =VLOOKUP(C5,'Top Redes'!A:D,4,0) -> 119452.2 | G5: =IFERROR(VLOOKUP($A5,'319'!$B:$H,7,0),0) -> 15137.6
A6: 1274396000470 | B6: DAMASCENO E DAMASCENO LTDA | C6: REDE DAMASCENO-PORTAL/PRINCESA | D6: SUPERMERCADO PRINCESA | E6: MIRANDA | F6: =VLOOKUP(C6,'Top Redes'!A:D,4,0) -> 119452.2 | G6: =IFERROR(VLOOKUP($A6,'319'!$B:$H,7,0),0) -> 204.87
A7: 1274396000632 | B7: DAMASCENO E DAMASCENO LTDA | C7: REDE DAMASCENO-PORTAL/PRINCESA | D7: PORTAL ATACADO | E7: ANASTACIO | F7: =VLOOKUP(C7,'Top Redes'!A:D,4,0) -> 119452.2 | G7: =IFERROR(VLOOKUP($A7,'319'!$B:$H,7,0),0) -> 49122.34
A8: 1274396000713 | B8: DAMASCENO E DAMASCENO LTDA | C8: REDE DAMASCENO-PORTAL/PRINCESA | D8: SUPERMERCADOS PRINCESA | E8: MIRANDA | F8: =VLOOKUP(C8,'Top Redes'!A:D,4,0) -> 119452.2 | G8: =IFERROR(VLOOKUP($A8,'319'!$B:$H,7,0),0) -> 7357.77
A9: 1274396000802 | B9: DAMASCENO E DAMASCENO LTDA | C9: REDE DAMASCENO-PORTAL/PRINCESA | D9: SUPERMERCADOS PRINCESA | E9: CHAPADAO DO SUL | F9: =VLOOKUP(C9,'Top Redes'!A:D,4,0) -> 119452.2 | G9: =IFERROR(VLOOKUP($A9,'319'!$B:$H,7,0),0) -> 9335.77
A10: 1274396000985 | B10: DAMASCENO E DAMASCENO LTDA | C10: REDE DAMASCENO-PORTAL/PRINCESA | D10: DAMASCENO E DAMASCENO LTDA | E10: MIRANDA | F10: =VLOOKUP(C10,'Top Redes'!A:D,4,0) -> 119452.2 | G10: =IFERROR(VLOOKUP($A10,'319'!$B:$H,7,0),0) -> 12951.56
A11: 1274396001019 | B11: DAMASCENO E DAMASCENO LTDA | C11: REDE DAMASCENO-PORTAL/PRINCESA | D11: PORTAL ATACADO | E11: AQUIDAUANA | F11: =VLOOKUP(C11,'Top Redes'!A:D,4,0) -> 119452.2 | G11: =IFERROR(VLOOKUP($A11,'319'!$B:$H,7,0),0) -> 35735.35
A12: 2318826000129 | B12: VRA COMERCIO LTDA | C12: REDE VRA / MEGA | D12: SM VERATTI - LJ01 | E12: COSTA RICA | F12: =VLOOKUP(C12,'Top Redes'!A:D,4,0) -> 624018.3 | G12: =IFERROR(VLOOKUP($A12,'319'!$B:$H,7,0),0) -> 40129.08
A13: 2318826000200 | B13: VRA COMERCIO LTDA | C13: REDE VRA / MEGA | D13: MEGA ATACADISTA LJ2 | E13: CORUMBA | F13: =VLOOKUP(C13,'Top Redes'!A:D,4,0) -> 624018.3 | G13: =IFERROR(VLOOKUP($A13,'319'!$B:$H,7,0),0) -> 221339.41
A14: 2318826000390 | B14: VRA COMERCIO LTDA | C14: REDE VRA / MEGA | D14: SM VERATTI - LJ53 | E14: IVINHEMA | F14: =VLOOKUP(C14,'Top Redes'!A:D,4,0) -> 624018.3 | G14: =IFERROR(VLOOKUP($A14,'319'!$B:$H,7,0),0) -> 64515.33
... A160: 46876542000204 | B160: SUPERMERCADO FERNANDES PRODUTOS ALIMENTI | C160: REDE SUP FERNANDES F | D160: FERNANDES SUPERMERCADO | E160: LADARIO | F160: =VLOOKUP(C160,'Top Redes'!A:D,4,0) -> 27961.821 | G160: =IFERROR(VLOOKUP($A160,'319'!$B:$H,7,0),0) -> 7051.11

Sheet redes
A1: CNPJ | B1: Razao | C1: Cidade | D1: Rede | E1: Fantasia | F1: VALOR | G1: A FATURAR
A2: 1178113 | B2: JOICE MOTTA MENDES | C2: CAMPO GRANDE | E2: CONVENIENCIA SERVE MAIS | F2: =IFERROR(VLOOKUP($A2,'319'!$B:$H,7,0),0) -> 0 | G2: =SUMIFS('12.326ana'!$C:$C,'12.326ana'!$M:$M,redes!A2) -> 0
A3: 6498132 | B3: GUSTAVO LORENTZ NEIVA | C3: CAMPO GRANDE | E3: GUGU | F3: =IFERROR(VLOOKUP($A3,'319'!$B:$H,7,0),0) -> 0 | G3: =SUMIFS('12.326ana'!$C:$C,'12.326ana'!$M:$M,redes!A3) -> 0
A4: 8442843 | B4: ALMEIZINO BARBOSA DE SOUZA | C4: CAMPO GRANDE | E4: PANIFICADORA BARBOSA | F4: =IFERROR(VLOOKUP($A4,'319'!$B:$H,7,0),0) -> 0 | G4: =SUMIFS('12.326ana'!$C:$C,'12.326ana'!$M:$M,redes!A4) -> 0
A5: 24921130 | B5: HEMERSON MATHEUS CHIELI | C5: CORUMBA | E5: MERCADO CHIELI | F5: =IFERROR(VLOOKUP($A5,'319'!$B:$H,7,0),0) -> 0 | G5: =SUMIFS('12.326ana'!$C:$C,'12.326ana'!$M:$M,redes!A5) -> 0
A6: 29174163 | B6: ELIAS LONGO JUNIOR | C6: CAMPO GRANDE | E6: ESQUINA DO FRANGO | F6: =IFERROR(VLOOKUP($A6,'319'!$B:$H,7,0),0) -> 0 | G6: =SUMIFS('12.326ana'!$C:$C,'12.326ana'!$M:$M,redes!A6) -> 0
A7: 32893116 | B7: CLEBERSON DA SILVA RODRIGUES | C7: CAMPO GRANDE | F7: =IFERROR(VLOOKUP($A7,'319'!$B:$H,7,0),0) -> 0 | G7: =SUMIFS('12.326ana'!$C:$C,'12.326ana'!$M:$M,redes!A7) -> 0
A8: 32926146 | B8: ELISVALDO MARTINS DE MACEDO | C8: COSTA RICA | E8: ART PAES PANIFICADORA | F8: =IFERROR(VLOOKUP($A8,'319'!$B:$H,7,0),0) -> 0 | G8: =SUMIFS('12.326ana'!$C:$C,'12.326ana'!$M:$M,redes!A8) -> 0
A9: 33571120 | B9: ADRIANO APARECIDO GAMARRA (VEND 106) | C9: CAMPO GRANDE | E9: ADRIAN | F9: =IFERROR(VLOOKUP($A9,'319'!$B:$H,7,0),0) -> 0 | G9: =SUMIFS('12.326ana'!$C:$C,'12.326ana'!$M:$M,redes!A9) -> 0
A10: 34263348 | B10: DALVA MARTINS ZANDONADI | C10: CAMPO GRANDE | E10: MERCADO FLORES | F10: =IFERROR(VLOOKUP($A10,'319'!$B:$H,7,0),0) -> 0 | G10: =SUMIFS('12.326ana'!$C:$C,'12.326ana'!$M:$M,redes!A10) -> 0
A11: 37302396 | B11: ANTONIO MARCOS PEREIRA | C11: DOURADOS | E11: MERCADO ARCO IRIS | F11: =IFERROR(VLOOKUP($A11,'319'!$B:$H,7,0),0) -> 0 | G11: =SUMIFS('12.326ana'!$C:$C,'12.326ana'!$M:$M,redes!A11) -> 0
A12: 41223136 | B12: MARCELO JOSE DA SILVA | C12: CASSILANDIA | E12: PANF J.K | F12: =IFERROR(VLOOKUP($A12,'319'!$B:$H,7,0),0) -> 0 | G12: =SUMIFS('12.326ana'!$C:$C,'12.326ana'!$M:$M,redes!A12) -> 0
A13: 42116422 | B13: MARIA DAS DORES PINHEIRO DOMINGOS | C13: CAMPO GRANDE | E13: MERCADO MAIZA | F13: =IFERROR(VLOOKUP($A13,'319'!$B:$H,7,0),0) -> 0 | G13: =SUMIFS('12.326ana'!$C:$C,'12.326ana'!$M:$M,redes!A13) -> 0
A14: 48093513 | B14: JOSE HUMBERTO MACHADO MACEDO | C14: CAMPO GRANDE | E14: BIROSCA CONVENIENCIA | F14: =IFERROR(VLOOKUP($A14,'319'!$B:$H,7,0),0) -> 0 | G14: =SUMIFS('12.326ana'!$C:$C,'12.326ana'!$M:$M,redes!A14) -> 0
A15: 49871102 | B15: CLAUDIA FREITAS DE SOUZA | C15: CAMPO GRANDE | E15: MERCADO MORAES | F15: =IFERROR(VLOOKUP($A15,'319'!$B:$H,7,0),0) -> 0 | G15: =SUMIFS('12.326ana'!$C:$C,'12.326ana'!$M:$M,redes!A15) -> 0
A16: 62672118 | B16: HEMERSOM PRADO ELIAS | C16: APARECIDA DO TABOADO | E16: MINI MERCADO TABOADO | F16: =IFERROR(VLOOKUP($A16,'319'!$B:$H,7,0),0) -> 0 | G16: =SUMIFS('12.326ana'!$C:$C,'12.326ana'!$M:$M,redes!A16) -> 0
A17: 63064111 | B17: NILTON ARAUJO SILVA | C17: DOURADOS | E17: MERCADO VITORIA | F17: =IFERROR(VLOOKUP($A17,'319'!$B:$H,7,0),0) -> 0 | G17: =SUMIFS('12.326ana'!$C:$C,'12.326ana'!$M:$M,redes!A17) -> 0
A18: 63354110 | B18: KLEITON SAFFE DELMONTES | C18: CAMPO GRANDE | E18: MERCADO PAULISTA | F18: =IFERROR(VLOOKUP($A18,'319'!$B:$H,7,0),0) -> 0 | G18: =SUMIFS('12.326ana'!$C:$C,'12.326ana'!$M:$M,redes!A18) -> 0
A19: 63556170 | B19: MARCELO DOS SANTOS RIBEIRO | C19: DOURADOS | E19: MARCELO DOS SANTOS RIBEIRO | F19: =IFERROR(VLOOKUP($A19,'319'!$B:$H,7,0),0) -> 0 | G19: =SUMIFS('12.326ana'!$C:$C,'12.326ana'!$M:$M,redes!A19) -> 0
... A21: 64261158 | B21: JAIME DOS SANTOS | C21: CAMPO GRANDE | E21: LANCHONETE BAMBINA | F21: =IFERROR(VLOOKUP($A21,'319'!$B:$H,7,0),0) -> 0 | G21: =SUMIFS('12.326ana'!$C:$C,'12.326ana'!$M:$M,redes!A21) -> 0
A22: 71488103 | B22: CLEITON DA SILVA ANJOLIN | C22: DOURADOS | F22: =IFERROR(VLOOKUP($A22,'319'!$B:$H,7,0),0) -> 0 | G22: =SUMIFS('12.326ana'!$C:$C,'12.326ana'!$M:$M,redes!A22) -> 0
A23: 73799351 | B23: LEIDE DE ALENCAR KLEIN | C23: CAMPO GRANDE | E23: ESCOLA PADRE BLANDINO | F23: =IFERROR(VLOOKUP($A23,'319'!$B:$H,7,0),0) -> 0 | G23: =SUMIFS('12.326ana'!$C:$C,'12.326ana'!$M:$M,redes!A23) -> 0
A24: 77511174 | B24: ELIZANGELA COSTA PEIXOTO | C24: CAMPO GRANDE | E24: MERCEARIA ANACHE | F24: =IFERROR(VLOOKUP($A24,'319'!$B:$H,7,0),0) -> 0 | G24: =SUMIFS('12.326ana'!$C:$C,'12.326ana'!$M:$M,redes!A24) -> 0
A25: 81935170 | B25: DORIANE BENITES | C25: CAMPO GRANDE | E25: LAV AKY LAVANDERIA | F25: =IFERROR(VLOOKUP($A25,'319'!$B:$H,7,0),0) -> 0 | G25: =SUMIFS('12.326ana'!$C:$C,'12.326ana'!$M:$M,redes!A25) -> 0
A26: 82174164 | B26: SUZI MEIRE VITTORAZI | C26: CAMPO GRANDE | E26: SUZI MEIRE VITTORAZI | F26: =IFERROR(VLOOKUP($A26,'319'!$B:$H,7,0),0) -> 0 | G26: =SUMIFS('12.326ana'!$C:$C,'12.326ana'!$M:$M,redes!A26) -> 0
A27: 83890122 | B27: JOSE TIAGO DOS SANTOS | C27: NAVIRAI | E27: MRC IDEAL | F27: =IFERROR(VLOOKUP($A27,'319'!$B:$H,7,0),0) -> 0 | G27: =SUMIFS('12.326ana'!$C:$C,'12.326ana'!$M:$M,redes!A27) -> 0
A28: 90526155 | B28: ADRIANI ZIGLIOLI | C28: CAMPO GRANDE | F28: =IFERROR(VLOOKUP($A28,'319'!$B:$H,7,0),0) -> 0 | G28: =SUMIFS('12.326ana'!$C:$C,'12.326ana'!$M:$M,redes!A28) -> 0
A29: 92278140 | B29: WEBER BARCELOS PAULINO | C29: CASSILANDIA | E29: MEGA BEER | F29: =IFERROR(VLOOKUP($A29,'319'!$B:$H,7,0),0) -> 0 | G29: =SUMIFS('12.326ana'!$C:$C,'12.326ana'!$M:$M,redes!A29) -> 0
A30: 93906188 | B30: EDNA CONCEICAO DE OLIVEIRA | C30: CAMPO GRANDE | E30: PADARIA YULLIAYAME | F30: =IFERROR(VLOOKUP($A30,'319'!$B:$H,7,0),0) -> 0 | G30: =SUMIFS('12.326ana'!$C:$C,'12.326ana'!$M:$M,redes!A30) -> 0
A31: 93981120 | B31: EVANILSON SIGARINI SOARES | C31: CORUMBA | E31: EVANILSON SIGARINI SOARES | F31: =IFERROR(VLOOKUP($A31,'319'!$B:$H,7,0),0) -> 0 | G31: =SUMIFS('12.326ana'!$C:$C,'12.326ana'!$M:$M,redes!A31) -> 0
A32: 94980101 | B32: LUCIANE PEREIRA | C32: CAMPO GRANDE | E32: LUA CONVENIENCIA | F32: =IFERROR(VLOOKUP($A32,'319'!$B:$H,7,0),0) -> 0 | G32: =SUMIFS('12.326ana'!$C:$C,'12.326ana'!$M:$M,redes!A32) -> 0
A33: 96680121 | B33: FERNANDO WEINERT | C33: CAMPO GRANDE | E33: FERNANDO | F33: =IFERROR(VLOOKUP($A33,'319'!$B:$H,7,0),0) -> 0 | G33: =SUMIFS('12.326ana'!$C:$C,'12.326ana'!$M:$M,redes!A33) -> 0
A34: 97030120 | B34: ROGERIO ROBEIRO AMORIM | C34: CAMPO GRANDE | E34: PANIF HAWAY | F34: =IFERROR(VLOOKUP($A34,'319'!$B:$H,7,0),0) -> 0 | G34: =SUMIFS('12.326ana'!$C:$C,'12.326ana'!$M:$M,redes!A34) -> 0
A35: 104112166 | B35: ZENAIDE MARTINS DA SILVA | C35: DOURADOS | E35: MERCEARIA MARTIANO | F35: =IFERROR(VLOOKUP($A35,'319'!$B:$H,7,0),0) -> 0 | G35: =SUMIFS('12.326ana'!$C:$C,'12.326ana'!$M:$M,redes!A35) -> 0
A36: 108857654 | B36: LORETE TAWIL | C36: CAMPO GRANDE | E36: HORA DO LANCHE | F36: =IFERROR(VLOOKUP($A36,'319'!$B:$H,7,0),0) -> 0 | G36: =SUMIFS('12.326ana'!$C:$C,'12.326ana'!$M:$M,redes!A36) -> 0
A37: 109531167 | B37: CLEOMAR MAIA | C37: CAMPO GRANDE | E37: CLEOMAR DEPOSITO | F37: =IFERROR(VLOOKUP($A37,'319'!$B:$H,7,0),0) -> 0 | G37: =SUMIFS('12.326ana'!$C:$C,'12.326ana'!$M:$M,redes!A37) -> 0
A38: 109830156 | B38: CLEONICE R DE LIMA | C38: CAMPO GRANDE | E38: MERCEARIA VIEIRA | F38: =IFERROR(VLOOKUP($A38,'319'!$B:$H,7,0),0) -> 0 | G38: =SUMIFS('12.326ana'!$C:$C,'12.326ana'!$M:$M,redes!A38) -> 0
A39: 109917197 | B39: ROSANGELA FREIRE DE CASTRO | C39: ANASTACIO | E39: MERCEARIA CONVENIENCIA DA NEGA | F39: =IFERROR(VLOOKUP($A39,'319'!$B:$H,7,0),0) -> 0 | G39: =SUMIFS('12.326ana'!$C:$C,'12.326ana'!$M:$M,redes!A39) -> 0
A40: 120380161 | B40: ALEXANDRA DOS SANTOS RODRIGUES | C40: CAMPO GRANDE | E40: ALEXANDRA DOS SANTOS RODRIGUES | F40: =IFERROR(VLOOKUP($A40,'319'!$B:$H,7,0),0) -> 0 | G40: =SUMIFS('12.326ana'!$C:$C,'12.326ana'!$M:$M,redes!A40) -> 0
... A42: 121313182 | B42: EMERSON DIAS DOS SANTOS | C42: CAMPO GRANDE | E42: MERCADO DIAS | F42: =IFERROR(VLOOKUP($A42,'319'!$B:$H,7,0),0) -> 0 | G42: =SUMIFS('12.326ana'!$C:$C,'12.326ana'!$M:$M,redes!A42) -> 0
...

Sheet Equipe
A1: COD | B1: NOME | C1: COORD | D1: NOME COORD | E1: EQUIPE
A2: 100 | B2: BALCÃO | C2: 998 | D2: GERENCIA | E2: 1
A3: 130 | B3: CLT - JOSE LUCA | C3: 906 | D3: THIAGO - MC.KA | E3: 6
A4: 135 | B4: CLT - TALITA GO | C4: 906 | D4: THIAGO - MC.KA | E4: 6
A5: 211 | B5: PJ - PAULA REGI | C5: 906 | D5: THIAGO - MC.KA | E5: 1
A6: 301 | B6: CLT - MAX DOS S | C6: 906 | D6: THIAGO - MC.KA | E6: 1
A7: 507 | B7: CLT - CLAUDIMIR | C7: 906 | D7: THIAGO - MC.KA | E7: 1
A8: 702 | B8: CLT - RENATA MA | C8: 906 | D8: THIAGO - MC.KA | E8: 1
A9: 703 | B9: PJ - FERNANDO A | C9: 902 | D9: CLAUDIO - VAREJ | E9: 1
A10: 704 | B10: CLT - GILBERTO | C10: 910 | D10: JONATAS - VAREJ | E10: 1
A11: 705 | B11: CLT - TATIANA M | C11: 910 | D11: JONATAS - VAREJ | E11: 1
A12: 706 | B12: PJ - NILVANIA L | C12: 902 | D12: CLAUDIO - VAREJ | E12: 1
A13: 707 | B13: CLT - LORENA DA | C13: 910 | D13: JONATAS - VAREJ | E13: 1
... A27: 800 | B27: CLT - CRISTIAN | C27: 902 | D27: CLAUDIO - VAREJ | E27: 6
A28: 759 | B28: BRUNO DE SOUZA NUNES | C28: 904 | D28: DANIELLE CORTES MORAIS
